1) check dependencies:
	PyUSB - version must be at least 1.0.0a2
	fix with: "sudo pip install --ugrade --pre pyusb"

2) check USB device: ( Looking for ID="19a2:5001" )
	"lsusb"
	
	You should see something like:
	
	Bus 002 Device 045: ID 19a2:5001  
	Bus 002 Device 001: ID 1d6b:0002 Linux Foundation 2.0 root hub
	Bus 008 Device 001: ID 1d6b:0001 Linux Foundation 1.1 root hub
	Bus 007 Device 001: ID 1d6b:0001 Linux Foundation 1.1 root hub
	Bus 006 Device 001: ID 1d6b:0001 Linux Foundation 1.1 root hub
	Bus 005 Device 001: ID 1d6b:0001 Linux Foundation 1.1 root hub
	Bus 001 Device 002: ID 064e:a133 Suyin Corp. 
	Bus 001 Device 001: ID 1d6b:0002 Linux Foundation 2.0 root hub
	Bus 004 Device 001: ID 1d6b:0001 Linux Foundation 1.1 root hub
	Bus 003 Device 001: ID 1d6b:0001 Linux Foundation 1.1 root hub
	
3) check permissions:
	lsusb -v -s NUMBER_OF_DEVICE ("lsusb -v -s 45")
    
    if is there warning:
	Bus 002 Device 045: ID 19a2:5001  
	Couldn't open device, some information will be missing
	....
    than you can run your programs with "sudo" OR
    workaround:
    copy 70_SICK.rules to /etc/udev/rules.d/
    	sudo cp 70_SICK.rules /etc/udev/rules.d/70_SICK.rules
    
    create new group SICK:
    	sudo groupadd sick
    
    add yourself to that group:
    	sudo useradd -a -G sick <your_username>
    
    unplug device & restart udev:
        sudo udevadm trigger
    
    restart your machine, to apply new rules.
    plug device again and chech again lsusb.

4) test connection with python
	python LaserScanner.py
    if there is error: "USBError: [Errno 13] Access denied (insufficient permissions)"
        workaround is probably not working - report me and I'll try fix it.
    try "sudo python LaserScanner.py" - it should work.
    
    
    
    
    
    
    